<mujoco model="staccatoe">
  <compiler angle="radian" meshdir="meshes/"/>
  <option timestep="0.001" gravity="0 0 -9.81" />
  <asset>
   <texture name="texplane" type="2d" builtin="checker" rgb1=".2 .3 .4" rgb2=".1 0.15 0.2" width="512" height="512"/> 
    <material name='MatPlane' reflectance='0.5' texture="texplane" texrepeat="1 1" texuniform="true"/> 
    <mesh name="body_link" file="body_link.stl"/>
    <mesh name="hiproll_link" file="hiproll_link.stl"/>
    <mesh name="hippitch_link" file="hippitch_link.stl"/>
    <mesh name="shank_link" file="shank_link.stl"/>
    <mesh name="anklepitch_link" file="anklepitch_link.stl"/>
    <mesh name="foot_link" file="foot_link.stl"/>
    <mesh name="toe_link" file="toe_link.stl"/>
  </asset>
  <default class="body">
    <joint type="hinge"/>
    </default>
  <worldbody>
  <geom name="floor" friction="1 .8 .8" pos="0 0 0" size="500 500 0.125" type="plane" material="MatPlane" condim="3" conaffinity="1" contype="1" group="2" rgba="0.8 0.9 0.8 1"></geom>
    <light cutoff="100" diffuse="1 1 1" dir="-0 0 -1.3" directional="true" exponent="1" pos="0 0 1.3" specular=".1 .1 .1" castshadow="false"/>
    <body name="body_link" pos="0 0 2" quat="1 0 0 0">
      <inertial pos="-21.34e-3 -0.3e-3 120.27e-3" quat="-1.28299513e-04 9.99999980e-01 -1.50459610e-04 2.04502754e-07" mass="5.568" diaginertia="0.03264195 0.10433947 0.1237959"/>
      <!-- <geom type="mesh" contype="0" conaffinity="0" group="1" density="0" mesh="body_link"/> -->
    <!-- <geom type="box" size="0.067 0.0945 0.04125" pos="0 0 0.05" density="0" condim="3" contype="1" conaffinity="1" rgba="1 1 1 0"/> -->
    <geom type="mesh" mesh="body_link"/>
    <site name="torso_link_sensor_site" pos="0 0 0" quat="1 0 0 0" size="0.01 0.01 0.01"/>
    <freejoint name="root"/>
    <body name="R_hiproll_link" pos="0.0222 0 -0.0875" quat="1 0 0 0">
      <inertial pos="-0.0066 0.01323 3.6e-09" quat="0.488937 0.526537 0.507515 0.475529" mass="1.122" diaginertia="0.00153836 0.00109931 0.000880715"/>
      <joint name="hiproll" pos="0 0 0" axis="1 0 0" armature="0.0081162" damping="0.5"/>
      <geom type="mesh" contype="0" conaffinity="0" group="1" density="0" mesh="hiproll_link"/>
      <!-- <geom type="mesh" mesh="hiproll_link"/> -->
      <body name="R_hippitch_link" pos="0 0.001 0" quat="1 0 0 0">
        <inertial pos="0.01046 -0.00323 -0.19348" quat="0.725413 0.0193201 0.00425213 0.688029" mass="4.84" diaginertia="0.0310905 0.0293569 0.00623362"/>
        <joint name="hippitch" pos="0 0 0" axis="0 1 0" armature="0.0081162" damping="0.5"/>
        <geom type="mesh" contype="0" conaffinity="0" group="1" density="0" mesh="hippitch_link"/>
        <!-- <geom type="mesh" mesh="hippitch_link"/> -->
        <body name="R_shank_link" pos="0 0.0005 -0.348">
          <inertial pos="0.00825 -0.00155 -0.18718" quat="0.999827 0.00976881 0.000144032 -0.0158336" mass="1.443" diaginertia="0.0141586 0.0136363 0.00123458"/>
          <joint name="kneepitch" pos="0 0 0" axis="0 1 0" armature="0.09712" damping="0.5"/>
          <geom type="mesh" contype="0" conaffinity="0" group="1" density="0" mesh="shank_link"/>
          <!-- <geom type="mesh" mesh="shank_link"/> -->
          <body name="R_ankle_link" pos="0 0 -0.355" quat="0.965926 0 -0.258819 0">
            <inertial pos="0.00575 -7.13e-08 3.39e-08" quat="0.500005 0.499999 -0.499995 0.500001" mass="0.147" diaginertia="6.9036e-05 6.2695e-05 2.2525e-05"/>
            <joint name="anklepitch" pos="0 0 0" axis="0 1 0" armature="0.01731555" damping="0.5"/>
            <geom type="mesh" contype="0" conaffinity="0" group="1" density="0" mesh="anklepitch_link"/>
            <!-- <geom type="mesh" mesh="anklepitch_link"/> -->
            <body name="R_foot_link">
              <inertial pos="0.00213 -1e-05 -0.03047" quat="0.36438 0.60573 0.606456 0.364044" mass="0.581" diaginertia="0.00211369 0.00200352 0.000472025"/>
              <joint name="ankleroll" pos="0 0 0" axis="1 0 0" armature="0.01731555" damping="0.5"/>
              <geom type="mesh" contype="0" conaffinity="0" group="1" density="0" mesh="foot_link"/>
              <!-- <geom type="sphere" size="0.031146055" pos="-0.05183996 0 -0.02249384" density="0" condim="3" contype="1" conaffinity="1" rgba="1 1 1 0"/> -->
              <geom type="sphere" size="0.031146055" pos="-0.05183996 0 -0.02249384" density="0" condim="3" contype="1" conaffinity="1"/>
              <!-- <geom type="mesh" mesh="foot_link"/> -->
              <body name="R_toe_center_link" pos="0.0849784 0 -0.0854385" quat="0.965926 0 0.258819 0">
                <inertial pos="0.02459 -2.66e-06 -0.01919" quat="3.463e-05 0.804503 -5.22563e-06 0.593948" mass="0.317" diaginertia="0.000555501 0.000344317 0.000311118"/>
                <joint name="toepitch" pos="0 0 0" axis="0 1 0" armature="0.01731555" damping="0.5"/>
                <geom type="mesh" contype="0" conaffinity="0" group="1" density="0" mesh="toe_link"/>
                <!-- <geom type="mesh" mesh="toe_link"/> -->
                <!-- <geom type="box" size="0.05 0.045 0.00698665" pos="0.034 0 -0.03748665" density="0" condim="3" contype="1" conaffinity="1" rgba="1 1 1 0"/> -->
                <geom type="sphere" size="0.01" pos="0.0765 0.03 -0.03604021" density="0" condim="3" contype="1" conaffinity="1" />
                <geom type="sphere" size="0.01" pos="0.0765 -0.03 -0.03604021" density="0" condim="3" contype="1" conaffinity="1"/>
                <geom type="sphere" size="0.01" pos="-0.0085 0.03 -0.03604021" density="0" condim="3" contype="1" conaffinity="1"/>
                <geom type="sphere" size="0.01" pos="-0.0085 -0.03 -0.03604021" density="0" condim="3" contype="1" conaffinity="1"/>
              </body>
            </body>
          </body>
        </body>
      </body>
    </body>
    </body>
  </worldbody>

  <actuator>
    <motor name="hip_roll" joint="hiproll"/>
    <motor name="hip_pitch" joint="hippitch"/>
    <motor name="knee_pitch" joint="kneepitch" ctrllimited="true" ctrlrange="-250 250"/>
    <motor name="ankle_pitch" joint="anklepitch" ctrllimited="true" ctrlrange="-100 100"/>
    <motor name="ankle_roll" joint="ankleroll" ctrllimited="true" ctrlrange="-70 70"/>
    <motor name="toe_pitch" joint="toepitch" ctrllimited="true" ctrlrange="-70 70"/>
  </actuator>

  <sensor>
    <accelerometer name="accelerometer" site="torso_link_sensor_site"/>
    <gyro name="gyro" site="torso_link_sensor_site"/>
  </sensor>

  <keyframe>
    <key name="init_pose" qpos="0.001551 0.010996 0.3 0.9638109 0 0.266587 0  0.000 -1.9495328 2.666461671 -1.4 -0.000 0" qvel="0 0 0 0 0 0 0 0 0 0 0 0" />
    <!-- <key name="init_pose" qpos="0.001551 0.010996 0.5 1 0 0 0  0 0 0 0 0 0" qvel="0 0 0 0 0 0 0 0 0 0 0 0" /> -->
  </keyframe>
<!-- 
  <equality>
    <weld body1="body_link" body2="world" relpose="0 0 -2 1 0 0 0"/>
  </equality> -->

</mujoco>
